Workbook

Sheet jamon parma
A1: STOCK PARMA
E2: CHICOS | F2: GRANDES | G2: EXTRAGRANDES
B3: DIAS PROCESO | E3: 365 | F3: 395 | G3: =+F3+30 -> 425
A4: FECHA SALAZON | B4: N° LOTE | C4: UNIDADES | D4: KILOS | E4: FECHA TERMINACION | F4: TAMAÑO
A5: 46126 | B5: 262E/01 | C5: 254 | D5: 2759 | E5: =+A5+$E$3 -> 46491 | F5: CHICO
A6: 46126 | B6: 262E/02 | C6: 498 | D6: 6000 | E6: =+A6+$E$3 -> 46491 | F6: GRANDE
A7: 46157 | B7: 262E/03 | C7: 92 | D7: 1007 | E7: =+A7+$E$3 -> 46522 | F7: CHICO
A8: 46157 | B8: 262E/04 | C8: 223 | D8: 2679 | E8: =+A8+$E$3 -> 46522 | F8: GRANDE
A9: 46157 | B9: 262E/05 | C9: 52 | D9: 705 | E9: =+A9+$E$3 -> 46522 | F9: EXTRAGRANDE

Sheet jamon iberico
A1: STOCK IBERICO
E2: CHICOS | F2: GRANDES | G2: EXTRAGRANDES
B3: DIAS PROCESO | E3: 365 | F3: 395 | G3: =+F3+30 -> 425
A4: FECHA SALAZON | B4: N° LOTE | C4: UNIDADES | D4: KILOS | E4: FECHA TERMINACION | F4: TAMAÑO
A5: 45825 | B5: 251E/01 | C5: 77 | D5: 844.5 | E5: =IF(F5="CHICO",A5+365,IF(F5="GRANDE",A5+395,IF(F5="EXTRAGRANDE",A5+425,""))) -> 46190 | F5: CHICO
A6: 45825 | B6: 251E/02 | C6: 120 | D6: 1449.5 | E6: =IF(F6="CHICO",A6+365,IF(F6="GRANDE",A6+395,IF(F6="EXTRAGRANDE",A6+425,""))) -> 46220 | F6: GRANDE
A7: 45833 | B7: 251E/03 | C7: 113 | D7: 1240.5 | E7: =IF(F7="CHICO",A7+365,IF(F7="GRANDE",A7+395,IF(F7="EXTRAGRANDE",A7+425,""))) -> 46198 | F7: CHICO
A8: 45833 | B8: 251E/04 | C8: 217 | D8: 2685.5 | E8: =IF(F8="CHICO",A8+365,IF(F8="GRANDE",A8+395,IF(F8="EXTRAGRANDE",A8+425,""))) -> 46228 | F8: GRANDE
A9: 45839 | B9: 251E/05 | C9: 195 | D9: 2134 | E9: =IF(F9="CHICO",A9+365,IF(F9="GRANDE",A9+395,IF(F9="EXTRAGRANDE",A9+425,""))) -> 46204 | F9: CHICO
A10: 45839 | B10: 251E/06 | C10: 508 | D10: 6247.5 | E10: =IF(F10="CHICO",A10+365,IF(F10="GRANDE",A10+395,IF(F10="EXTRAGRANDE",A10+425,""))) -> 46234 | F10: GRANDE
A11: 45847 | B11: 251E/07 | C11: 260 | D11: 2810 | E11: =IF(F11="CHICO",A11+365,IF(F11="GRANDE",A11+395,IF(F11="EXTRAGRANDE",A11+425,""))) -> 46212 | F11: CHICO
A12: 45847 | B12: 251E/08 | C12: 488 | D12: 5968 | E12: =IF(F12="CHICO",A12+365,IF(F12="GRANDE",A12+395,IF(F12="EXTRAGRANDE",A12+425,""))) -> 46242 | F12: GRANDE
A13: 45853 | B13: 251E/09 | C13: 248 | D13: 2657.5 | E13: =IF(F13="CHICO",A13+365,IF(F13="GRANDE",A13+395,IF(F13="EXTRAGRANDE",A13+425,""))) -> 46218 | F13: CHICO
A14: 45853 | B14: 251E/10 | C14: 482 | D14: 587.6 | E14: =IF(F14="CHICO",A14+365,IF(F14="GRANDE",A14+395,IF(F14="EXTRAGRANDE",A14+425,""))) -> 46248 | F14: GRANDE
A15: 45860 | B15: 251E/11 | C15: 219 | D15: 2398 | E15: =IF(F15="CHICO",A15+365,IF(F15="GRANDE",A15+395,IF(F15="EXTRAGRANDE",A15+425,""))) -> 46225 | F15: CHICO
A16: 45860 | B16: 251E/12 | C16: 386 | D16: 4675.5 | E16: =IF(F16="CHICO",A16+365,IF(F16="GRANDE",A16+395,IF(F16="EXTRAGRANDE",A16+425,""))) -> 46255 | F16: GRANDE
... A106: 46154 | B106: 261E/42 | C106: 54 | D106: 729 | E106: =IF(F106="CHICO",A106+365,IF(F106="GRANDE",A106+395,IF(F106="EXTRAGRANDE",A106+425,""))) -> 46579 | F106: EXTRAGRANDE

Sheet SALAME FUET
A1: STOCK FUET
B2: DIAS PROCESO | E2: 21
A3: FECHA SALAZON | B3: N° LOTE | C3: UNIDADES | D3: KILOS | E3: FECHA TERMINACION
A4: 46134 | B4: 265E/15 | C4: 6744 | D4: 1840 | E4: =+A4+$E$2 -> 46155
A5: 46141 | B5: 265E/16 | C5: 6720 | D5: 1820 | E5: =+A5+$E$2 -> 46162
A6: 46148 | B6: 265E/17 | C6: 4478 | D6: 1205 | E6: =+A6+$E$2 -> 46169
A7: 46149 | B7: 265E/18 | C7: 4464 | D7: 1197 | E7: =+A7+$E$2 -> 46170
A8: 46155 | B8: 265E/19 | C8: 4330 | D8: 1213 | E8: =+A8+$E$2 -> 46176
A9: 46156 | B9: 265E/20 | C9: 4522 | D9: 1222 | E9: =+A9+$E$2 -> 46177

Sheet PANCETA SALADA
A1: STOCK PANCETA SALADA
B2: DIAS PROCESO | E2: 5
A3: FECHA SALAZON | B3: N° LOTE | C3: UNIDADES | D3: KILOS | E3: FECHA TERMINACION
A4: 46156 | B4: 266E/14 | C4: 99 | D4: 349 | E4: =+A4+$E$2 -> 46161

Sheet BONDIOLA CURADA
A1: STOCK BONDIOLA
B2: DIAS PROCESO | E2: 65
A3: FECHA SALAZON | B3: N° LOTE | C3: UNIDADES | D3: KILOS | E3: FECHA TERMINACION
A4: 46141 | B4: 264E/13 | C4: 224 | D4: 494 | E4: =+A4+$E$2 -> 46206
A5: 46149 | B5: 264E/14 | C5: 224 | D5: 504.2 | E5: =+A5+$E$2 -> 46214
A6: 46155 | B6: 264E/15 | C6: 449 | D6: 964.5 | E6: =+A6+$E$2 -> 46220
A7: 46157 | B7: 264E/16 | C7: 448 | D7: 962 | E7: =+A7+$E$2 -> 46222

Sheet LOMO CURADO
A1: STOCK LOMO
B2: DIAS PROCESO | E2: =10+35 -> 45
A3: FECHA SALAZON | B3: N° LOTE | C3: UNIDADES | D3: KILOS | E3: FECHA TERMINACION
A4: 46121 | B4: 267E/03 | C4: 99 | D4: 261 | E4: =+A4+$E$2 -> 46166
A5: 46155 | B5: 267E/04 | C5: 103 | D5: 223 | E5: =+A5+$E$2 -> 46200

Sheet RAPIDISIMOS
A1: STOCK RAPIDISIMOS
B2: DIAS PROCESO | E2: 150
A3: FECHA SALAZON | B3: N° LOTE | C3: UNIDADES | D3: KILOS | E3: FECHA TERMINACION
A4: 46002 | B4: 258E/47 | C4: 598 | D4: 3618.5 | E4: =+A4+$E$2 -> 46152
A5: 46010 | B5: 258E/48 | C5: 502 | D5: 3064 | E5: =+A5+$E$2 -> 46160
A6: 46017 | B6: 258E/49 | C6: 602 | D6: 3621 | E6: =+A6+$E$2 -> 46167
A7: 46024 | B7: 268E/01 | C7: 492 | D7: 2929 | E7: =+A7+$E$2 -> 46174
A8: 46031 | B8: 268E/02 | C8: 599 | D8: 3463 | E8: =+A8+$E$2 -> 46181
A9: 46038 | B9: 268E/03 | C9: 440 | D9: 2680 | E9: =+A9+$E$2 -> 46188
A10: 46038 | B10: 268E/04 | C10: 138 | D10: 796.5 | E10: =+A10+$E$2 -> 46188
A11: 46045 | B11: 268E/05 | C11: 600 | D11: 3636 | E11: =+A11+$E$2 -> 46195
A12: 46050 | B12: 268E/06 | C12: 766 | D12: 4684.5 | E12: =+A12+$E$2 -> 46200
A13: 46057 | B13: 268E/07 | C13: 801 | D13: 4838 | E13: =+A13+$E$2 -> 46207
A14: 46065 | B14: 268E/08 | C14: 797 | D14: 4871 | E14: =+A14+$E$2 -> 46215
A15: 46073 | B15: 268E/09 | C15: 402 | D15: 2434 | E15: =+A15+$E$2 -> 46223
... A27: 46156 | B27: 268E/21 | C27: 704 | D27: 4479.5 | E27: =+A27+$E$2 -> 46306

Sheet RESUMEN STOCK PROCESO
A1: Fecha | B1: 46150
B3: EN PROCESO
B4: Unidades | C4: KG
A5: Jamon crudo -12m rendidor Doina
A6: Jamon crudo C/ Hueso Doina
A7: Panceta salada mini pieza Doina
A8: Jamon crudo -12m Iberico Doina | B8: =SUM(Tabla1[UNIDADES]) -> 24251 | C8: =SUM(Tabla1[KILOS]) -> 282947.1
A9: Jamon crudo 1/2-12m iberico Doina
A10: Jamon crudo -12m Parma doina | B10: =SUM(Tabla4[UNIDADES]) -> 1119 | C10: =SUM(Tabla4[KILOS]) -> 13150
A11: Pernil Delipork | B11: =SUM(Tabla9[UNIDADES]) -> 15639 | C11: =SUM(Tabla9[KILOS]) -> 97663
A12: Pernil mitades Delipork
A13: Jamon crudo 1/2-12m rendidor Doina
A14: Bondiola curada Doina | B14: =SUM(Tabla7[UNIDADES]) -> 1345 | C14: =SUM(Tabla7[KILOS]) -> 2924.7
A15: Bondiola mitades Doina
A16: Bondiola curada mini pieza Doina
A17: Lomo 1/2 curada Doina | B17: =SUM(Tabla8[UNIDADES]) -> 202 | C17: =SUM(Tabla8[KILOS]) -> 484
A18: Lomo mini pieza curada Doina
A19: Panceta salada Doina | B19: {=+Tabla6[UNIDADES]} -> 99 | C19: {=+Tabla6[KILOS]} -> 349
A20: Panceta salada mini pieza Doina
A21: Panceta ahumada Doina
A22: Panceta ahumada mini pieza Doina
A23: Salame puro cerdo doina
A24: Salame puro cerdo minipieza Doina
A25: Caja de regalo jamon crudo 1/2 Doina
A26: Fuet | B26: =SUM(Tabla5[UNIDADES]) -> 31258 | C26: =SUM(Tabla5[KILOS]) -> 8497
A27: Jamon Crudo Delipork
A28: Jamon Crudo mitades Delipork

Sheet stock terminado produccion
A1: Fecha | B1: 46142
B3: Unidades | C3: KG
A4: Jamon c/h c/Pezuña | B4: =SUMIF($A$24:$A$2001,"JAMON C/H C/PEZUÑA",$C$24:$C$2001) -> 89 | C4: =SUMIF($A$24:$A$2001,"JAMON C/H C/PEZUÑA",$F$24:$F$2001) -> 758.3
A5: Original Entero | B5: =SUMIF($A$24:$A$2001,"ORIGINAL",$C$24:$C$2001) -> 511 | C5: =SUMIF($A$24:$A$2001,"ORIGINAL",$F$24:$F$2001) -> 2601.5
A6: Original Mitades
A7: Parma Entero | B7: =SUMIF($A$24:$A$2001,"PARMA",$C$24:$C$2001) -> 6559 | C7: =SUMIF($A$24:$A$2001,"PARMA",$F$24:$F$2001) -> 37767.5
A8: Parma Mitades
A9: Rendidor Entero | B9: =SUMIF($A$24:$A$2001,"RENDIDOR",$C$24:$C$2001) -> 2722 | C9: =SUMIF($A$24:$A$2001,"RENDIDOR",$F$24:$F$2001) -> 12782
A10: Rendidor Mitades
A11: Pernil | B11: =SUMIF($A$24:$A$2001,"PERNIL",$C$24:$C$2001) -> 169 | C11: =SUMIF($A$24:$A$2001,"PERNIL",$F$24:$F$2001) -> 645
A12: Pernil Mitades | B12: =SUMIF($A$24:$A$2001,"Pernil Mitades",$C$24:$C$2001) -> 0 | C12: =SUMIF($A$24:$A$2001,"Pernil Mitades",$F$24:$F$2001) -> 0
A13: Speck | B13: =SUMIF($A$24:$A$2001,"SPECK",$C$24:$C$2001) -> 1004 | C13: =SUMIF($A$24:$A$2001,"SPECK",$F$24:$F$2001) -> 4176
A14: Bondiola | B14: =SUMIF($A$24:$A$2001,"BONDIOLA",$C$24:$C$2001) -> 11429 | C14: =SUMIF($A$24:$A$2001,"BONDIOLA",$F$24:$F$2001) -> 15263.5
A15: Lomo Mitades
A16: Fuet
A17: Panceta ahumada
A18: Panceta Salada
A19: Paleta
A20: Paleta c/hueso
A21: Jamón c/hueso
A23: Producto | B23: Lote | C23: Unidades | D23: Kg Bruto | E23: Tara | F23: Kg Neto | G23: Envasado
A24: PARMA | B24: 232E / 17 | C24: 77 | D24: 462 | E24: 32 | F24: =+D24-E24 -> 430 | G24: 45404
A25: PARMA | B25: 232E / 17 | C25: 69 | D25: 425 | E25: 32 | F25: =+D25-E25 -> 393 | G25: 45404
A26: PARMA | B26: 232E / 22 | C26: 43 | D26: 263 | E26: 32 | F26: =+D26-E26 -> 231 | G26: 45426
A27: PARMA | B27: 232E /26 | C27: 68 | D27: 427 | E27: 32 | F27: 395 | G27: 45439
A28: PARMA | B28: 232E / 26 | C28: 66 | D28: 407 | E28: 32 | F28: 375 | G28: 45439
A29: PARMA | B29: 232E / 26 | C29: 66 | D29: 417 | E29: 32 | F29: 385 | G29: 45439
A30: PARMA | B30: 232E /28 | C30: 58 | D30: 354 | E30: 32 | F30: 322 | G30: 45440
A31: PARMA | B31: 232E / 28 | C31: 57 | D31: 298 | E31: 32 | F31: 266 | G31: 45440
A32: PARMA | B32: 232E /32 | C32: 61 | D32: 363 | E32: 32 | F32: 331 | G32: 45446
A33: PARMA | B33: 232E/35 | C33: 67 | D33: 356 | E33: 32 | F33: 324 | G33: 45446
A34: PARMA | B34: 232E/36 | C34: 69 | D34: 416 | E34: 32 | F34: 384 | G34: 45453
A35: PARMA | B35: 232E/36 | C35: 69 | D35: 389 | E35: 32 | F35: 357 | G35: 45453
A36: PARMA | B36: 232E /36 | C36: 69 | D36: 416 | E36: 32 | F36: =+D36-E36 -> 384 | G36: 45453
A37: PARMA | B37: 232E/39 | C37: 62 | D37: 380 | E37: 32 | F37: =+D37-E37 -> 348 | G37: 45454
A38: PARMA | B38: 232E/39 | C38: 62 | D38: 377 | E38: 32 | F38: =+D38-E38 -> 345 | G38: 45454
A39: PARMA | B39: 232E / 38 | C39: 53 | D39: 309 | E39: 32 | F39: =+D39-E39 -> 277 | G39: 45454
A40: PARMA | B40: 232E/ 38 | C40: 53 | D40: 336 | E40: 32 | F40: =+D40-E40 -> 304 | G40: 45454
A41: PARMA | B41: 232E/37 | C41: 70 | D41: 453 | E41: 32 | F41: =+D41-E41 -> 421 | G41: 45495
A42: PARMA | B42: 232R/41 | C42: 75 | D42: 427 | E42: 32 | F42: =+D42-E42 -> 395 | G42: 45505
...

Sheet stock expedicion
A1: Fecha | B1: 46142
B2: Unidades | C2: KG
A3: Jamon crudo -12m rendidor Doina | B3: =SUMIF($A$27:$A$2173,A3,$C$27:$C$2173) -> 11 | C3: =SUMIF($A$27:$A$2173,A3,$D$27:$D$2173) -> 59.32
A4: Jamon crudo C/ Hueso Doina | B4: =SUMIF($A$27:$A$2173,A4,$C$27:$C$2173) -> 55 | C4: =SUMIF($A$27:$A$2173,A4,$D$27:$D$2173) -> 413.17
A5: Panceta salada mini pieza Doina | B5: =SUMIF($A$27:$A$2173,A5,$C$27:$C$2173) -> 390 | C5: =SUMIF($A$27:$A$2173,A5,$D$27:$D$2173) -> 123.35
A6: Jamon crudo -12m Iberico Doina | B6: =SUMIF($A$27:$A$2173,A6,$C$27:$C$2173) -> 367 | C6: =SUMIF($A$27:$A$2173,A6,$D$27:$D$2173) -> 1978.43
A7: Jamon crudo 1/2-12m iberico Doina | B7: =SUMIF($A$27:$A$2173,A7,$C$27:$C$2173) -> 154 | C7: =SUMIF($A$27:$A$2173,A7,$D$27:$D$2173) -> 372.19
A8: Jamon crudo -12m Parma doina | B8: =SUMIF($A$27:$A$2173,A8,$C$27:$C$2173) -> 414 | C8: =SUMIF($A$27:$A$2173,A8,$D$27:$D$2173) -> 2287
A9: Pernil Delipork | B9: =SUMIF($A$27:$A$2173,A9,$C$27:$C$2173) -> 252 | C9: =SUMIF($A$27:$A$2173,A9,$D$27:$D$2173) -> 950.07
A10: Pernil mitades Delipork | B10: =SUMIF($A$27:$A$2173,A10,$C$27:$C$2173) -> 897 | C10: =SUMIF($A$27:$A$2173,A10,$D$27:$D$2173) -> 1691.41
A11: Jamon crudo 1/2-12m rendidor Doina | B11: =SUMIF($A$27:$A$2173,A11,$C$27:$C$2173) -> 564 | C11: =SUMIF($A$27:$A$2173,A11,$D$27:$D$2173) -> 1280.55
A12: Bondiola curada Doina | B12: =SUMIF($A$27:$A$2173,A12,$C$27:$C$2173) -> 492 | C12: =SUMIF($A$27:$A$2173,A12,$D$27:$D$2173) -> 634.23
A13: Bondiola mitades Doina | B13: =SUMIF($A$27:$A$2173,A13,$C$27:$C$2173) -> 7 | C13: =SUMIF($A$27:$A$2173,A13,$D$27:$D$2173) -> 4.57
A14: Bondiola curada mini pieza Doina | B14: =SUMIF($A$27:$A$2173,A14,$C$27:$C$2173) -> 11 | C14: =SUMIF($A$27:$A$2173,A14,$D$27:$D$2173) -> 5.2
... A25: Jamon Crudo mitades Delipork | B25: =SUMIF($A$27:$A$2173,A25,$C$27:$C$2173) -> 391 | C25: =SUMIF($A$27:$A$2173,A25,$D$27:$D$2173) -> 732.88
A28: Descripcion | B28: Cant | C28: Uni | D28: Kg | E28: Vencimiento | F28: Lote | G28: VidaUtil | H28: VidaUtilPorc
A29: Salame Fuet Doina | B29: 14 | C29: 140 | D29: 21 | E29: 05/09/2026 | F29: 265E/13 | G29: 110 | H29: 91
A30: Salame Fuet Doina | B30: 59 | C30: 590 | D30: 88.5 | E30: 10/09/2026 | F30: 265E/14 | G30: 115 | H30: 95
A31: Jamon crudo -12m rendidor Doina | B31: 3 | C31: 11 | D31: 59.32 | E31: 22/06/2027 | F31: 241E/69 | G31: 400 | H31: 55
A32: Jamon crudo C/ Hueso Doina | B32: 1 | C32: 1 | D32: 7.65 | E32: 16/02/2027 | F32: 241E/45 | G32: 274 | H32: 38
A33: Jamon crudo C/ Hueso Doina | B33: 53 | C33: 53 | D33: 397.8 | E33: 28/04/2027 | F33: 212E/42 | G33: 345 | H33: 47
A34: Jamon crudo C/ Hueso Doina | B34: 1 | C34: 1 | D34: 7.72 | E34: 05/07/2027 | F34: 212E/42 | G34: 413 | H34: 57
A35: Panceta salada mini pieza Doina | B35: 13 | C35: 390 | D35: 123.35 | E35: 10/09/2026 | F35: 266E/13 | G35: 115 | H35: 95
A36: Jamon crudo -12m Iberico Doina | B36: 1 | C36: 2 | D36: 9.43 | E36: 29/05/2027 | F36: 221E/127 | G36: 376 | H36: 52
A37: Jamon crudo -12m Iberico Doina | B37: 8 | C37: 24 | D37: 139.94 | E37: 07/06/2027 | F37: 231/6 | G37: 385 | H37: 53
A38: Jamon crudo -12m Iberico Doina | B38: 23 | C38: 67 | D38: 384.71 | E38: 28/06/2027 | F38: 231/6 | G38: 406 | H38: 56
A39: Jamon crudo -12m Iberico Doina | B39: 1 | C39: 3 | D39: 14.18 | E39: 28/06/2027 | F39: 231E/13 | G39: 406 | H39: 56
A40: Jamon crudo -12m Iberico Doina | B40: 15 | C40: 45 | D40: 255.37 | E40: 01/07/2027 | F40: 231/6 | G40: 409 | H40: 56
... A88: Jamon Crudo mitades Delipork | B88: 31 | C88: 293 | D88: 553.33 | E88: 22/01/2027 | F88: 258E/41 | G88: 249 | H88: 92

Sheet RESUMEN STOCK
A1: Fecha | B1: 46150
B3: STOCK EXPEDICION | D3: STOCK PRODUCCION | F3: STOCK PROCESO
B4: Unidades | C4: KG | D4: Unidades | E4: KG | F4: Unidades | G4: KG
A5: Jamon crudo -12m rendidor Doina | B5: =+'stock expedicion'!B3 -> 11 | C5: =+'stock expedicion'!C3 -> 59.32 | D5: =+'stock terminado produccion'!B9 -> 2722 | E5: =+'stock terminado produccion'!C9 -> 12782 | F5: =+'RESUMEN STOCK PROCESO'!B5 -> 0 | G5: =+'RESUMEN STOCK PROCESO'!C5 -> 0
A6: Jamon crudo C/ Hueso Doina | B6: =+'stock expedicion'!B4 -> 55 | C6: =+'stock expedicion'!C4 -> 413.17 | D6: =+'stock terminado produccion'!B4 -> 89 | E6: =+'stock terminado produccion'!C4 -> 758.3 | F6: =+'RESUMEN STOCK PROCESO'!B6 -> 0 | G6: =+'RESUMEN STOCK PROCESO'!C6 -> 0
A7: Panceta salada mini pieza Doina | B7: =+'stock expedicion'!B5 -> 390 | C7: =+'stock expedicion'!C5 -> 123.35 | F7: =+'RESUMEN STOCK PROCESO'!B7 -> 0 | G7: =+'RESUMEN STOCK PROCESO'!C7 -> 0
A8: Jamon crudo -12m Iberico Doina | B8: =+'stock expedicion'!B6 -> 367 | C8: =+'stock expedicion'!C6 -> 1978.43 | D8: =+'stock terminado produccion'!B5 -> 511 | E8: =+'stock terminado produccion'!C5 -> 2601.5 | F8: =+'RESUMEN STOCK PROCESO'!B8 -> 24251 | G8: =+'RESUMEN STOCK PROCESO'!C8 -> 282947.1
A9: Jamon crudo 1/2-12m iberico Doina | B9: =+'stock expedicion'!B7 -> 154 | C9: =+'stock expedicion'!C7 -> 372.19 | F9: =+'RESUMEN STOCK PROCESO'!B9 -> 0 | G9: =+'RESUMEN STOCK PROCESO'!C9 -> 0
A10: Jamon crudo -12m Parma doina | B10: =+'stock expedicion'!B8 -> 414 | C10: =+'stock expedicion'!C8 -> 2287 | D10: =+'stock terminado produccion'!B7 -> 6559 | E10: =+'stock terminado produccion'!C7 -> 37767.5 | F10: =+'RESUMEN STOCK PROCESO'!B10 -> 1119 | G10: =+'RESUMEN STOCK PROCESO'!C10 -> 13150
A11: Pernil Delipork | B11: =+'stock expedicion'!B9 -> 252 | C11: =+'stock expedicion'!C9 -> 950.07 | D11: =+'stock terminado produccion'!B11 -> 169 | E11: =+'stock terminado produccion'!C11 -> 645 | F11: =+'RESUMEN STOCK PROCESO'!B11 -> 15639 | G11: =+'RESUMEN STOCK PROCESO'!C11 -> 97663
A12: Pernil mitades Delipork | B12: =+'stock expedicion'!B10 -> 897 | C12: =+'stock expedicion'!C10 -> 1691.41 | D12: =+'stock terminado produccion'!B12 -> 0 | E12: =+'stock terminado produccion'!C12 -> 0 | F12: =+'RESUMEN STOCK PROCESO'!B12 -> 0 | G12: =+'RESUMEN STOCK PROCESO'!C12 -> 0
A13: Speck | D13: =+'stock terminado produccion'!B13 -> 1004 | E13: =+'stock terminado produccion'!C13 -> 4176
A14: Jamon crudo 1/2-12m rendidor Doina | B14: =+'stock expedicion'!B11 -> 564 | C14: =+'stock expedicion'!C11 -> 1280.55 | F14: =+'RESUMEN STOCK PROCESO'!B13 -> 0 | G14: =+'RESUMEN STOCK PROCESO'!C13 -> 0
A15: Bondiola curada Doina | B15: =+'stock expedicion'!B12 -> 492 | C15: =+'stock expedicion'!C12 -> 634.23 | D15: =+'stock terminado produccion'!B14 -> 11429 | E15: =+'stock terminado produccion'!C14 -> 15263.5 | F15: =+'RESUMEN STOCK PROCESO'!B14 -> 1345 | G15: =+'RESUMEN STOCK PROCESO'!C14 -> 2924.7
A16: Bondiola mitades Doina | B16: =+'stock expedicion'!B13 -> 7 | C16: =+'stock expedicion'!C13 -> 4.57 | F16: =+'RESUMEN STOCK PROCESO'!B15 -> 0 | G16: =+'RESUMEN STOCK PROCESO'!C15 -> 0
A17: Bondiola curada mini pieza Doina | B17: =+'stock expedicion'!B14 -> 11 | C17: =+'stock expedicion'!C14 -> 5.2 | F17: =+'RESUMEN STOCK PROCESO'!B16 -> 0 | G17: =+'RESUMEN STOCK PROCESO'!C16 -> 0
A18: Lomo 1/2 curada Doina | B18: =+'stock expedicion'!B15 -> 1 | C18: =+'stock expedicion'!C15 -> 1.05 | F18: =+'RESUMEN STOCK PROCESO'!B17 -> 202 | G18: =+'RESUMEN STOCK PROCESO'!C17 -> 484
A19: Lomo mini pieza curada Doina | B19: =+'stock expedicion'!B16 -> 19 | C19: =+'stock expedicion'!C16 -> 7.54 | F19: =+'RESUMEN STOCK PROCESO'!B18 -> 0 | G19: =+'RESUMEN STOCK PROCESO'!C18 -> 0
A20: Panceta salada Doina | B20: =+'stock expedicion'!B17 -> 7 | C20: =+'stock expedicion'!C17 -> 5.6 | F20: =+'RESUMEN STOCK PROCESO'!B19 -> 99 | G20: =+'RESUMEN STOCK PROCESO'!C19 -> 349
A21: Panceta salada mini pieza Doina | F21: =+'RESUMEN STOCK PROCESO'!B20 -> 0 | G21: =+'RESUMEN STOCK PROCESO'!C20 -> 0
A22: Panceta ahumada Doina | B22: =+'stock expedicion'!B18 -> 63 | C22: =+'stock expedicion'!C18 -> 108.9 | F22: =+'RESUMEN STOCK PROCESO'!B21 -> 0 | G22: =+'RESUMEN STOCK PROCESO'!C21 -> 0
A23: Panceta ahumada mini pieza Doina | B23: =+'stock expedicion'!B19 -> 810 | C23: =+'stock expedicion'!C19 -> 262.12 | F23: =+'RESUMEN STOCK PROCESO'!B22 -> 0 | G23: =+'RESUMEN STOCK PROCESO'!C22 -> 0
A24: Salame puro cerdo doina | B24: =+'stock expedicion'!B20 -> 654 | C24: =+'stock expedicion'!C20 -> 693.29 | F24: =+'RESUMEN STOCK PROCESO'!B23 -> 0 | G24: =+'RESUMEN STOCK PROCESO'!C23 -> 0
A25: Salame puro cerdo minipieza Doina | B25: =+'stock expedicion'!B21 -> 26 | C25: =+'stock expedicion'!C21 -> 6.95 | F25: =+'RESUMEN STOCK PROCESO'!B24 -> 0 | G25: =+'RESUMEN STOCK PROCESO'!C24 -> 0
A26: Caja de regalo jamon crudo 1/2 Doina | B26: =+'stock expedicion'!B22 -> 5 | C26: =+'stock expedicion'!C22 -> 13.54 | F26: =+'RESUMEN STOCK PROCESO'!B25 -> 0 | G26: =+'RESUMEN STOCK PROCESO'!C25 -> 0
A27: Fuet | F27: =+'RESUMEN STOCK PROCESO'!B26 -> 31258 | G27: =+'RESUMEN STOCK PROCESO'!C26 -> 8497
A28: Jamon Crudo Delipork | B28: =+'stock expedicion'!B24 -> 567 | C28: =+'stock expedicion'!C24 -> 2140.37 | F28: =+'RESUMEN STOCK PROCESO'!B27 -> 0 | G28: =+'RESUMEN STOCK PROCESO'!C27 -> 0
A29: Jamon Crudo mitades Delipork | B29: =+'stock expedicion'!B25 -> 391 | C29: =+'stock expedicion'!C25 -> 732.88 | F29: =+'RESUMEN STOCK PROCESO'!B28 -> 0 | G29: =+'RESUMEN STOCK PROCESO'!C28 -> 0
